Workbook
Name ComponentList: OFFSET('Component Catalogue'!$C$5,0,0,COUNTA('Component Catalogue'!$C$5:$C$150),1)

Sheet Read Me
A1: UI / UX Build Effort Estimator
A2: Draft v0.1 - starting values to be replaced with team experience-based hours
A4: Purpose
A5: What this is | B5: A simple, explainable Excel reference for estimating the developer effort of modern web applications (UI plus the back-end APIs behind them) when responding to RFPs. A person reads the tables, picks the components and complexity, and the workbook totals the hours.
A6: What it is not | B6: Not a pricing tool, not a project plan, and not an estimator for agent / data-pipeline development. It only covers web UI and the API layer that serves it.
A8: Who uses it
A9: RFP / bid responder | B9: Primary user (solution architect or tech lead). Turns RFP text into page and component counts. Works in the Estimator and How to choose sections.
A10: Sales / pricing team | B10: Reads the Estimator summary: total hours, person-days and indicative duration, with and without AI assistance.
A11: Reviewers / leadership | B11: Read the Complexity Rubric and Component Catalogue to confirm the definitions and hours are sensible.
A12: UI and back-end developers | B12: Maintain the numbers: enter experience-based hours in the Component Catalogue and Page Bundles, and log delivered projects in the Calibration log (Assumptions).
A14: What the hours cover
A15: Included | B15: Developer build effort plus writing unit tests, for a typical first implementation by an average developer (not person-specific).
A16: Excluded | B16: UAT and integration testing, project management, requirements gathering, DevOps, database design, data pipelines, agent / RAG development.
A17: Platform | B17: Modern web apps only (Next.js / React baseline). No mobile or desktop applications.
A19: How to use (5 steps)
A20: 1. Count pages | B20: From the RFP, list the page types (login, dashboards, admin, etc.). Decide how many are Simple, Medium or Complex using the page definitions on the Page Templates sheet.
A21: 2. Enter pages | B21: On the Estimator, type the counts into Section A. The hours per page come from the Page Templates sheet. Use the Page Explorer under Section A to see exactly which components make up any page and level.
A22: 3. Add shared / special components | B22: In Section B pick extra components from the dropdown (app shell, navigation, Kanban board, pivot table, etc.), choose a complexity and enter a quantity.
A23: 4. Add backend APIs | B23: In Section C enter how many endpoints of each type you expect. Use 'Typical API endpoints' on Page Templates as a guide.
A24: 5. Read the result | B24: The summary at the top of the Estimator shows the total hours and person-days WITHOUT AI and WITH AI assistance. Review assumptions before quoting.
A26: How to choose - RFP wording to inputs
A27: "N login / sign-in screens" | B27: Page type: Login & authentication page. Add Authentication endpoint in Section C.
A28: "Dashboards / analytics views" | B28: Page type: Dashboard / analytics page. Add Aggregation / analytics endpoints in Section C.
A29: "Admin screens / user management" | B29: Page type: Admin / configuration page. Add Role-based UI rendering in Section B and Authorisation layer in Section C.
A30: "Search / list / master data screens" | B30: Page type: List / search page, plus Detail / record page and Form / data-entry page for the record screens.
A31: "Chatbot / assistant" | B31: Page type: AI chat assistant page. Add an Agent / LLM-facing endpoint in Section C.
A32: "Workflow / approval screens" | B32: Page types: Wizard / guided workflow page and Agent / workflow monitor page.
A33: "Reports / downloads" | B33: Page type: Report & export page. Add Export / report endpoints in Section C.
A34: "Integrates with N systems" | B34: External system integration endpoint x N in Section C.
A35: "SSO required" | B35: Login page at Complex, Authentication endpoint at Complex, Role-based UI rendering in Section B.
A36: "Kanban, pivot tables, tree views" | B36: Not in any page template - add them individually in Section B.
A37: Not sure about complexity | B37: Use the Complexity Advisor sheet: pick the statement that fits for each dimension and it returns the level. Or use Medium by default (Complexity Rubric, Rule 2).
A39: Sheet guide
A40: Estimator | B40: The only sheet most users need. Inputs and the final totals.
A41: Summary | B41: One-page view for sales and clients: headline totals, where the hours go, top page drivers, and a scenario comparison (baseline, current settings, what-if).
A42: Complexity Advisor | B42: Answer seven questions about a page or component and it recommends Simple, Medium or Complex using the rubric rules, with the reason and the hours.
A43: Complexity Rubric | B43: Generic rules for Simple / Medium / Complex.
A44: Component Catalogue | B44: Every UI and API component with Simple / Medium / Complex definitions, unit, and hours (without and with AI).
A45: Page Templates | B45: Page-level definitions and hours per page type and level. Calculated from Page Bundles.
A46: Page Bundles | B46: The component recipe behind each page template. Edit to tune a template.
...

Sheet Estimator
A1: UI / UX Build Effort Estimator
A2: Enter counts in the blue cells. Sample inputs (1 login, 3 analytics, 4 admin pages) are pre-filled - overwrite them for your bid.
A4: Project / RFP name | B4: Sample project
A5: Team size (used only for indicative duration) | B5: 3
A7: ESTIMATE SUMMARY | B7: Without AI | C7: With AI | D7: Notes
A8: A. UI pages (hours) | B8: =H30 | C8: =B8*(1-Assumptions!$B$5) | D8: Pages from the page templates
A9: B. Additional shared components (hours) | B9: =F64 | C9: =B9*(1-Assumptions!$B$5) | D9: App shell, navigation and other individual components
A10: C. Backend APIs (hours) | B10: =H78 | C10: =B10*(1-Assumptions!$B$5) | D10: Endpoints and services
A11: Technology factor | B11: =Assumptions!$B$6 | C11: =Assumptions!$B$6 | D11: Set on the Assumptions sheet (1.00 = baseline stack)
A12: TOTAL ESTIMATED EFFORT (hours) | B12: =SUM(B8:B10)*B11 | C12: =SUM(C8:C10)*C11 | D12: Developer build + unit testing only. Excludes UAT, integration testing, PM and requirements gathering.
A13: Person-days | B13: =B12/Assumptions!$B$7 | C13: =C12/Assumptions!$B$7 | D13: ="Based on "&Assumptions!$B$7&" hours per person-day"
A14: Indicative duration (weeks, at team size above) | B14: =IFERROR(B12/($B$5*Assumptions!$B$8),0) | C14: =IFERROR(C12/($B$5*Assumptions!$B$8),0) | D14: ="Assumes "&Assumptions!$B$8&" productive hours per person-week"
A15: ="AI-assist reduction applied in the With AI column: "&TEXT(Assumptions!$B$5,"0%")&" (placeholder - see Assumptions)"
A17: A. UI PAGES - enter page counts. Row total = #Simple x hrs + #Medium x hrs + #Complex x hrs (see Page Explorer below)
A18: Page type | B18: # Simple | C18: # Medium | D18: # Complex | E18: Hrs per Simple page | F18: Hrs per Medium page | G18: Hrs per Complex page | H18: Total hours (without AI)
A19: Login & authentication page | B19: 0 | C19: 1 | D19: 0 | E19: =IFERROR(INDEX('Page Templates'!$G$5:$G$15,MATCH($A19,'Page Templates'!$A$5:$A$15,0)),0) | F19: =IFERROR(INDEX('Page Templates'!$H$5:$H$15,MATCH($A19,'Page Templates'!$A$5:$A$15,0)),0) | G19: =IFERROR(INDEX('Page Templates'!$I$5:$I$15,MATCH($A19,'Page Templates'!$A$5:$A$15,0)),0) | H19: =B19*E19+C19*F19+D19*G19
A20: Dashboard / analytics page | B20: 0 | C20: 2 | D20: 1 | E20: =IFERROR(INDEX('Page Templates'!$G$5:$G$15,MATCH($A20,'Page Templates'!$A$5:$A$15,0)),0) | F20: =IFERROR(INDEX('Page Templates'!$H$5:$H$15,MATCH($A20,'Page Templates'!$A$5:$A$15,0)),0) | G20: =IFERROR(INDEX('Page Templates'!$I$5:$I$15,MATCH($A20,'Page Templates'!$A$5:$A$15,0)),0) | H20: =B20*E20+C20*F20+D20*G20
A21: List / search page | B21: 0 | C21: 0 | D21: 0 | E21: =IFERROR(INDEX('Page Templates'!$G$5:$G$15,MATCH($A21,'Page Templates'!$A$5:$A$15,0)),0) | F21: =IFERROR(INDEX('Page Templates'!$H$5:$H$15,MATCH($A21,'Page Templates'!$A$5:$A$15,0)),0) | G21: =IFERROR(INDEX('Page Templates'!$I$5:$I$15,MATCH($A21,'Page Templates'!$A$5:$A$15,0)),0) | H21: =B21*E21+C21*F21+D21*G21
A22: Detail / record page | B22: 0 | C22: 0 | D22: 0 | E22: =IFERROR(INDEX('Page Templates'!$G$5:$G$15,MATCH($A22,'Page Templates'!$A$5:$A$15,0)),0) | F22: =IFERROR(INDEX('Page Templates'!$H$5:$H$15,MATCH($A22,'Page Templates'!$A$5:$A$15,0)),0) | G22: =IFERROR(INDEX('Page Templates'!$I$5:$I$15,MATCH($A22,'Page Templates'!$A$5:$A$15,0)),0) | H22: =B22*E22+C22*F22+D22*G22
A23: Form / data-entry page | B23: 0 | C23: 0 | D23: 0 | E23: =IFERROR(INDEX('Page Templates'!$G$5:$G$15,MATCH($A23,'Page Templates'!$A$5:$A$15,0)),0) | F23: =IFERROR(INDEX('Page Templates'!$H$5:$H$15,MATCH($A23,'Page Templates'!$A$5:$A$15,0)),0) | G23: =IFERROR(INDEX('Page Templates'!$I$5:$I$15,MATCH($A23,'Page Templates'!$A$5:$A$15,0)),0) | H23: =B23*E23+C23*F23+D23*G23
A24: Wizard / guided workflow page | B24: 0 | C24: 0 | D24: 0 | E24: =IFERROR(INDEX('Page Templates'!$G$5:$G$15,MATCH($A24,'Page Templates'!$A$5:$A$15,0)),0) | F24: =IFERROR(INDEX('Page Templates'!$H$5:$H$15,MATCH($A24,'Page Templates'!$A$5:$A$15,0)),0) | G24: =IFERROR(INDEX('Page Templates'!$I$5:$I$15,MATCH($A24,'Page Templates'!$A$5:$A$15,0)),0) | H24: =B24*E24+C24*F24+D24*G24
A25: Admin / configuration page | B25: 1 | C25: 2 | D25: 1 | E25: =IFERROR(INDEX('Page Templates'!$G$5:$G$15,MATCH($A25,'Page Templates'!$A$5:$A$15,0)),0) | F25: =IFERROR(INDEX('Page Templates'!$H$5:$H$15,MATCH($A25,'Page Templates'!$A$5:$A$15,0)),0) | G25: =IFERROR(INDEX('Page Templates'!$I$5:$I$15,MATCH($A25,'Page Templates'!$A$5:$A$15,0)),0) | H25: =B25*E25+C25*F25+D25*G25
A26: AI chat assistant page | B26: 0 | C26: 0 | D26: 0 | E26: =IFERROR(INDEX('Page Templates'!$G$5:$G$15,MATCH($A26,'Page Templates'!$A$5:$A$15,0)),0) | F26: =IFERROR(INDEX('Page Templates'!$H$5:$H$15,MATCH($A26,'Page Templates'!$A$5:$A$15,0)),0) | G26: =IFERROR(INDEX('Page Templates'!$I$5:$I$15,MATCH($A26,'Page Templates'!$A$5:$A$15,0)),0) | H26: =B26*E26+C26*F26+D26*G26
A27: Agent / workflow monitor page | B27: 0 | C27: 0 | D27: 0 | E27: =IFERROR(INDEX('Page Templates'!$G$5:$G$15,MATCH($A27,'Page Templates'!$A$5:$A$15,0)),0) | F27: =IFERROR(INDEX('Page Templates'!$H$5:$H$15,MATCH($A27,'Page Templates'!$A$5:$A$15,0)),0) | G27: =IFERROR(INDEX('Page Templates'!$I$5:$I$15,MATCH($A27,'Page Templates'!$A$5:$A$15,0)),0) | H27: =B27*E27+C27*F27+D27*G27
A28: Report & export page | B28: 0 | C28: 0 | D28: 0 | E28: =IFERROR(INDEX('Page Templates'!$G$5:$G$15,MATCH($A28,'Page Templates'!$A$5:$A$15,0)),0) | F28: =IFERROR(INDEX('Page Templates'!$H$5:$H$15,MATCH($A28,'Page Templates'!$A$5:$A$15,0)),0) | G28: =IFERROR(INDEX('Page Templates'!$I$5:$I$15,MATCH($A28,'Page Templates'!$A$5:$A$15,0)),0) | H28: =B28*E28+C28*F28+D28*G28
A29: Content / landing page | B29: 0 | C29: 0 | D29: 0 | E29: =IFERROR(INDEX('Page Templates'!$G$5:$G$15,MATCH($A29,'Page Templates'!$A$5:$A$15,0)),0) | F29: =IFERROR(INDEX('Page Templates'!$H$5:$H$15,MATCH($A29,'Page Templates'!$A$5:$A$15,0)),0) | G29: =IFERROR(INDEX('Page Templates'!$I$5:$I$15,MATCH($A29,'Page Templates'!$A$5:$A$15,0)),0) | H29: =B29*E29+C29*F29+D29*G29
A30: Total - UI pages | B30: =SUM(B19:B29) | C30: =SUM(C19:C29) | D30: =SUM(D19:D29) | H30: =SUM(H19:H29)
A32: PAGE EXPLORER - pick a page type and level to see exactly which components make up its hours
A33: Page type (choose) | B33: Login & authentication page | E33: Level (choose) | F33: Medium
A34: What this level means | B34: =IFERROR(INDEX('Page Templates'!$D$5:$F$15,MATCH($B$33,'Page Templates'!$A$5:$A$15,0),MATCH($F$33,{"Simple","Medium","Complex"},0)),"")
A35: Component in this page | B35: Level | C35: Qty | D35: Hrs each | E35: Hours | F35: What this level of the component looks like
A36: =IF($I36="","",INDEX('Page Bundles'!$B$5:$B$300,$I36)) | B36: =IF($I36="","",INDEX('Page Bundles'!$F$5:$H$300,$I36,MATCH($F$33,{"Simple","Medium","Complex"},0))) | C36: =IF($I36="","",INDEX('Page Bundles'!$C$5:$E$300,$I36,MATCH($F$33,{"Simple","Medium","Complex"},0))) | D36: =IF($I36="","",E36/C36) | E36: =IF($I36="","",INDEX('Page Bundles'!$I$5:$K$300,$I36,MATCH($F$33,{"Simple","Medium","Complex"},0))) | F36: =IF($I36="","",IFERROR(INDEX('Component Catalogue'!$E$5:$G$150,MATCH($A36,'Component Catalogue'!$C$5:$C$150,0),MATCH($B36,{"Simple","Medium","Complex"},0)),"")) | I36: =IFERROR(MATCH($B$33&"|"&1,CHOOSE(MATCH($F$33,{"Simple","Medium","Complex"},0),'Page Bundles'!$L$5:$L$300,'Page Bundles'!$M$5:$M$300,'Page Bundles'!$N$5:$N$300),0),"")
A37: =IF($I37="","",INDEX('Page Bundles'!$B$5:$B$300,$I37)) | B37: =IF($I37="","",INDEX('Page Bundles'!$F$5:$H$300,$I37,MATCH($F$33,{"Simple","Medium","Complex"},0))) | C37: =IF($I37="","",INDEX('Page Bundles'!$C$5:$E$300,$I37,MATCH($F$33,{"Simple","Medium","Complex"},0))) | D37: =IF($I37="","",E37/C37) | E37: =IF($I37="","",INDEX('Page Bundles'!$I$5:$K$300,$I37,MATCH($F$33,{"Simple","Medium","Complex"},0))) | F37: =IF($I37="","",IFERROR(INDEX('Component Catalogue'!$E$5:$G$150,MATCH($A37,'Component Catalogue'!$C$5:$C$150,0),MATCH($B37,{"Simple","Medium","Complex"},0)),"")) | I37: =IFERROR(MATCH($B$33&"|"&2,CHOOSE(MATCH($F$33,{"Simple","Medium","Complex"},0),'Page Bundles'!$L$5:$L$300,'Page Bundles'!$M$5:$M$300,'Page Bundles'!$N$5:$N$300),0),"")
A38: =IF($I38="","",INDEX('Page Bundles'!$B$5:$B$300,$I38)) | B38: =IF($I38="","",INDEX('Page Bundles'!$F$5:$H$300,$I38,MATCH($F$33,{"Simple","Medium","Complex"},0))) | C38: =IF($I38="","",INDEX('Page Bundles'!$C$5:$E$300,$I38,MATCH($F$33,{"Simple","Medium","Complex"},0))) | D38: =IF($I38="","",E38/C38) | E38: =IF($I38="","",INDEX('Page Bundles'!$I$5:$K$300,$I38,MATCH($F$33,{"Simple","Medium","Complex"},0))) | F38: =IF($I38="","",IFERROR(INDEX('Component Catalogue'!$E$5:$G$150,MATCH($A38,'Component Catalogue'!$C$5:$C$150,0),MATCH($B38,{"Simple","Medium","Complex"},0)),"")) | I38: =IFERROR(MATCH($B$33&"|"&3,CHOOSE(MATCH($F$33,{"Simple","Medium","Complex"},0),'Page Bundles'!$L$5:$L$300,'Page Bundles'!$M$5:$M$300,'Page Bundles'!$N$5:$N$300),0),"")
A39: =IF($I39="","",INDEX('Page Bundles'!$B$5:$B$300,$I39)) | B39: =IF($I39="","",INDEX('Page Bundles'!$F$5:$H$300,$I39,MATCH($F$33,{"Simple","Medium","Complex"},0))) | C39: =IF($I39="","",INDEX('Page Bundles'!$C$5:$E$300,$I39,MATCH($F$33,{"Simple","Medium","Complex"},0))) | D39: =IF($I39="","",E39/C39) | E39: =IF($I39="","",INDEX('Page Bundles'!$I$5:$K$300,$I39,MATCH($F$33,{"Simple","Medium","Complex"},0))) | F39: =IF($I39="","",IFERROR(INDEX('Component Catalogue'!$E$5:$G$150,MATCH($A39,'Component Catalogue'!$C$5:$C$150,0),MATCH($B39,{"Simple","Medium","Complex"},0)),"")) | I39: =IFERROR(MATCH($B$33&"|"&4,CHOOSE(MATCH($F$33,{"Simple","Medium","Complex"},0),'Page Bundles'!$L$5:$L$300,'Page Bundles'!$M$5:$M$300,'Page Bundles'!$N$5:$N$300),0),"")
A40: =IF($I40="","",INDEX('Page Bundles'!$B$5:$B$300,$I40)) | B40: =IF($I40="","",INDEX('Page Bundles'!$F$5:$H$300,$I40,MATCH($F$33,{"Simple","Medium","Complex"},0))) | C40: =IF($I40="","",INDEX('Page Bundles'!$C$5:$E$300,$I40,MATCH($F$33,{"Simple","Medium","Complex"},0))) | D40: =IF($I40="","",E40/C40) | E40: =IF($I40="","",INDEX('Page Bundles'!$I$5:$K$300,$I40,MATCH($F$33,{"Simple","Medium","Complex"},0))) | F40: =IF($I40="","",IFERROR(INDEX('Component Catalogue'!$E$5:$G$150,MATCH($A40,'Component Catalogue'!$C$5:$C$150,0),MATCH($B40,{"Simple","Medium","Complex"},0)),"")) | I40: =IFERROR(MATCH($B$33&"|"&5,CHOOSE(MATCH($F$33,{"Simple","Medium","Complex"},0),'Page Bundles'!$L$5:$L$300,'Page Bundles'!$M$5:$M$300,'Page Bundles'!$N$5:$N$300),0),"")
A41: =IF($I41="","",INDEX('Page Bundles'!$B$5:$B$300,$I41)) | B41: =IF($I41="","",INDEX('Page Bundles'!$F$5:$H$300,$I41,MATCH($F$33,{"Simple","Medium","Complex"},0))) | C41: =IF($I41="","",INDEX('Page Bundles'!$C$5:$E$300,$I41,MATCH($F$33,{"Simple","Medium","Complex"},0))) | D41: =IF($I41="","",E41/C41) | E41: =IF($I41="","",INDEX('Page Bundles'!$I$5:$K$300,$I41,MATCH($F$33,{"Simple","Medium","Complex"},0))) | F41: =IF($I41="","",IFERROR(INDEX('Component Catalogue'!$E$5:$G$150,MATCH($A41,'Component Catalogue'!$C$5:$C$150,0),MATCH($B41,{"Simple","Medium","Complex"},0)),"")) | I41: =IFERROR(MATCH($B$33&"|"&6,CHOOSE(MATCH($F$33,{"Simple","Medium","Complex"},0),'Page Bundles'!$L$5:$L$300,'Page Bundles'!$M$5:$M$300,'Page Bundles'!$N$5:$N$300),0),"")
A42: =IF($I42="","",INDEX('Page Bundles'!$B$5:$B$300,$I42)) | B42: =IF($I42="","",INDEX('Page Bundles'!$F$5:$H$300,$I42,MATCH($F$33,{"Simple","Medium","Complex"},0))) | C42: =IF($I42="","",INDEX('Page Bundles'!$C$5:$E$300,$I42,MATCH($F$33,{"Simple","Medium","Complex"},0))) | D42: =IF($I42="","",E42/C42) | E42: =IF($I42="","",INDEX('Page Bundles'!$I$5:$K$300,$I42,MATCH($F$33,{"Simple","Medium","Complex"},0))) | F42: =IF($I42="","",IFERROR(INDEX('Component Catalogue'!$E$5:$G$150,MATCH($A42,'Component Catalogue'!$C$5:$C$150,0),MATCH($B42,{"Simple","Medium","Complex"},0)),"")) | I42: =IFERROR(MATCH($B$33&"|"&7,CHOOSE(MATCH($F$33,{"Simple","Medium","Complex"},0),'Page Bundles'!$L$5:$L$300,'Page Bundles'!$M$5:$M$300,'Page Bundles'!$N$5:$N$300),0),"")
A43: =IF($I43="","",INDEX('Page Bundles'!$B$5:$B$300,$I43)) | B43: =IF($I43="","",INDEX('Page Bundles'!$F$5:$H$300,$I43,MATCH($F$33,{"Simple","Medium","Complex"},0))) | C43: =IF($I43="","",INDEX('Page Bundles'!$C$5:$E$300,$I43,MATCH($F$33,{"Simple","Medium","Complex"},0))) | D43: =IF($I43="","",E43/C43) | E43: =IF($I43="","",INDEX('Page Bundles'!$I$5:$K$300,$I43,MATCH($F$33,{"Simple","Medium","Complex"},0))) | F43: =IF($I43="","",IFERROR(INDEX('Component Catalogue'!$E$5:$G$150,MATCH($A43,'Component Catalogue'!$C$5:$C$150,0),MATCH($B43,{"Simple","Medium","Complex"},0)),"")) | I43: =IFERROR(MATCH($B$33&"|"&8,CHOOSE(MATCH($F$33,{"Simple","Medium","Complex"},0),'Page Bundles'!$L$5:$L$300,'Page Bundles'!$M$5:$M$300,'Page Bundles'!$N$5:$N$300),0),"")
A44: =IF($I44="","",INDEX('Page Bundles'!$B$5:$B$300,$I44)) | B44: =IF($I44="","",INDEX('Page Bundles'!$F$5:$H$300,$I44,MATCH($F$33,{"Simple","Medium","Complex"},0))) | C44: =IF($I44="","",INDEX('Page Bundles'!$C$5:$E$300,$I44,MATCH($F$33,{"Simple","Medium","Complex"},0))) | D44: =IF($I44="","",E44/C44) | E44: =IF($I44="","",INDEX('Page Bundles'!$I$5:$K$300,$I44,MATCH($F$33,{"Simple","Medium","Complex"},0))) | F44: =IF($I44="","",IFERROR(INDEX('Component Catalogue'!$E$5:$G$150,MATCH($A44,'Component Catalogue'!$C$5:$C$150,0),MATCH($B44,{"Simple","Medium","Complex"},0)),"")) | I44: =IFERROR(MATCH($B$33&"|"&9,CHOOSE(MATCH($F$33,{"Simple","Medium","Complex"},0),'Page Bundles'!$L$5:$L$300,'Page Bundles'!$M$5:$M$300,'Page Bundles'!$N$5:$N$300),0),"")
...

Sheet Summary
A1: Summary & Scenarios
A2: One-page view for sales and clients. Everything here is calculated from the Estimator - no inputs except the yellow what-if cells.
A4: Project / RFP | B4: =Estimator!B4
AA5: =Estimator!$A$19 | AB5: =Estimator!$H$19 | AC5: =AB5+(1000-ROW())/1000000
A6: Headline | B6: Without AI | C6: With AI | D6: Notes | AA6: =Estimator!$A$20 | AB6: =Estimator!$H$20 | AC6: =AB6+(1000-ROW())/1000000
A7: Total effort (hours) | B7: =Estimator!B12 | C7: =Estimator!C12 | D7: Developer build + unit testing | AA7: =Estimator!$A$21 | AB7: =Estimator!$H$21 | AC7: =AB7+(1000-ROW())/1000000
A8: Person-days | B8: =Estimator!B13 | C8: =Estimator!C13 | AA8: =Estimator!$A$22 | AB8: =Estimator!$H$22 | AC8: =AB8+(1000-ROW())/1000000
A9: Indicative duration (weeks) | B9: =Estimator!B14 | C9: =Estimator!C14 | D9: ="At a team of "&Estimator!B5 | AA9: =Estimator!$A$23 | AB9: =Estimator!$H$23 | AC9: =AB9+(1000-ROW())/1000000
AA10: =Estimator!$A$24 | AB10: =Estimator!$H$24 | AC10: =AB10+(1000-ROW())/1000000
A11: Where the hours go | AA11: =Estimator!$A$25 | AB11: =Estimator!$H$25 | AC11: =AB11+(1000-ROW())/1000000
A12: Area | B12: Hours (without AI) | C12: Hours (with AI) | D12: Share of total | AA12: =Estimator!$A$26 | AB12: =Estimator!$H$26 | AC12: =AB12+(1000-ROW())/1000000
A13: UI pages | B13: =Estimator!B8 | C13: =Estimator!C8 | D13: =IFERROR(B13/B$17,0) | AA13: =Estimator!$A$27 | AB13: =Estimator!$H$27 | AC13: =AB13+(1000-ROW())/1000000
A14: Additional shared components | B14: =Estimator!B9 | C14: =Estimator!C9 | D14: =IFERROR(B14/B$17,0) | AA14: =Estimator!$A$28 | AB14: =Estimator!$H$28 | AC14: =AB14+(1000-ROW())/1000000
A15: Backend APIs | B15: =Estimator!B10 | C15: =Estimator!C10 | D15: =IFERROR(B15/B$17,0) | AA15: =Estimator!$A$29 | AB15: =Estimator!$H$29 | AC15: =AB15+(1000-ROW())/1000000
A16: Technology factor adjustment | B16: =Estimator!B12-SUM(Estimator!B8:B10) | C16: =Estimator!C12-SUM(Estimator!C8:C10) | D16: =IFERROR(B16/B$17,0)
A17: Total | B17: =Estimator!B12 | C17: =Estimator!C12
A19: Top 5 UI page drivers
A20: Page type (ranked by hours) | B20: Hours (without AI) | C20: Share of UI hours | D20: # Simple / Medium / Complex
A21: =IF(F21="","",IF(INDEX($AB$5:$AB$15,F21)=0,"","1. "&INDEX($AA$5:$AA$15,F21))) | B21: =IF(A21="","",INDEX($AB$5:$AB$15,F21)) | C21: =IF(A21="","",IFERROR(B21/Estimator!$H$30,0)) | D21: =IF(A21="","",INDEX(Estimator!$B$19:$B$29,F21)&" / "&INDEX(Estimator!$C$19:$C$29,F21)&" / "&INDEX(Estimator!$D$19:$D$29,F21)) | F21: =IFERROR(MATCH(LARGE($AC$5:$AC$15,1),$AC$5:$AC$15,0),"")
A22: =IF(F22="","",IF(INDEX($AB$5:$AB$15,F22)=0,"","2. "&INDEX($AA$5:$AA$15,F22))) | B22: =IF(A22="","",INDEX($AB$5:$AB$15,F22)) | C22: =IF(A22="","",IFERROR(B22/Estimator!$H$30,0)) | D22: =IF(A22="","",INDEX(Estimator!$B$19:$B$29,F22)&" / "&INDEX(Estimator!$C$19:$C$29,F22)&" / "&INDEX(Estimator!$D$19:$D$29,F22)) | F22: =IFERROR(MATCH(LARGE($AC$5:$AC$15,2),$AC$5:$AC$15,0),"")
A23: =IF(F23="","",IF(INDEX($AB$5:$AB$15,F23)=0,"","3. "&INDEX($AA$5:$AA$15,F23))) | B23: =IF(A23="","",INDEX($AB$5:$AB$15,F23)) | C23: =IF(A23="","",IFERROR(B23/Estimator!$H$30,0)) | D23: =IF(A23="","",INDEX(Estimator!$B$19:$B$29,F23)&" / "&INDEX(Estimator!$C$19:$C$29,F23)&" / "&INDEX(Estimator!$D$19:$D$29,F23)) | F23: =IFERROR(MATCH(LARGE($AC$5:$AC$15,3),$AC$5:$AC$15,0),"")
A24: =IF(F24="","",IF(INDEX($AB$5:$AB$15,F24)=0,"","4. "&INDEX($AA$5:$AA$15,F24))) | B24: =IF(A24="","",INDEX($AB$5:$AB$15,F24)) | C24: =IF(A24="","",IFERROR(B24/Estimator!$H$30,0)) | D24: =IF(A24="","",INDEX(Estimator!$B$19:$B$29,F24)&" / "&INDEX(Estimator!$C$19:$C$29,F24)&" / "&INDEX(Estimator!$D$19:$D$29,F24)) | F24: =IFERROR(MATCH(LARGE($AC$5:$AC$15,4),$AC$5:$AC$15,0),"")
A25: =IF(F25="","",IF(INDEX($AB$5:$AB$15,F25)=0,"","5. "&INDEX($AA$5:$AA$15,F25))) | B25: =IF(A25="","",INDEX($AB$5:$AB$15,F25)) | C25: =IF(A25="","",IFERROR(B25/Estimator!$H$30,0)) | D25: =IF(A25="","",INDEX(Estimator!$B$19:$B$29,F25)&" / "&INDEX(Estimator!$C$19:$C$29,F25)&" / "&INDEX(Estimator!$D$19:$D$29,F25)) | F25: =IFERROR(MATCH(LARGE($AC$5:$AC$15,5),$AC$5:$AC$15,0),"")
A27: Scenario comparison (same scope, different assumptions)
B28: Baseline | C28: Current settings | D28: What-if (edit)
A29: Meaning | B29: No AI, baseline stack | C29: Values on the Assumptions sheet | D29: Your own values
A30: Technology factor | B30: 1 | C30: =Assumptions!$B$6 | D30: 1.25
A31: AI-assist reduction | B31: 0 | C31: =Assumptions!$B$5 | D31: 0.3
A32: Total hours | B32: =SUM(Estimator!$B$8:$B$10)*B30*(1-B31) | C32: =SUM(Estimator!$B$8:$B$10)*C30*(1-C31) | D32: =SUM(Estimator!$B$8:$B$10)*D30*(1-D31)
A33: Person-days | B33: =B32/Assumptions!$B$7 | C33: =C32/Assumptions!$B$7 | D33: =D32/Assumptions!$B$7
A34: Indicative weeks | B34: =IFERROR(B32/(Estimator!$B$5*Assumptions!$B$8),0) | C34: =IFERROR(C32/(Estimator!$B$5*Assumptions!$B$8),0) | D34: =IFERROR(D32/(Estimator!$B$5*Assumptions!$B$8),0)
A35: Difference vs baseline | B35: =IFERROR(B32/$B$32-1,0) | C35: =IFERROR(C32/$B$32-1,0) | D35: =IFERROR(D32/$B$32-1,0)
A37: Scenarios use the same scope as the Estimator. Total = (pages + shared components + APIs) x technology factor x (1 - AI reduction).

Sheet Complexity Advisor
A1: Complexity Advisor - which level is it?
A2: For each dimension pick the statement that best describes the item. The result follows the rubric rules: highest trigger wins, default to Medium.
A4: Item being assessed | B4: Sales performance dashboard
A5: Page type (to show hours) | B5: Dashboard / analytics page
A7: Step 1 - for each dimension pick the statement that fits best (leave blank if it does not apply)
A8: Dimension | B8: Pick the statement that fits | C8: Level | D8: Score
A9: Data source | B9: Live data (polling, websocket) or chained / dependent API calls | C9: =IF(B9="","",IFERROR(CHOOSE(MATCH(B9,'Complexity Rubric'!$B$5:$D$5,0),"Simple","Medium","Complex"),"Pick from list")) | D9: =IF(B9="","",IFERROR(MATCH(B9,'Complexity Rubric'!$B$5:$D$5,0),""))
A10: Interaction | B10: Sort, filter, select, open modals, submit forms | C10: =IF(B10="","",IFERROR(CHOOSE(MATCH(B10,'Complexity Rubric'!$B$6:$D$6,0),"Simple","Medium","Complex"),"Pick from list")) | D10: =IF(B10="","",IFERROR(MATCH(B10,'Complexity Rubric'!$B$6:$D$6,0),""))
A11: States & validation | B11: Field validation, success and error states, server-error mapping | C11: =IF(B11="","",IFERROR(CHOOSE(MATCH(B11,'Complexity Rubric'!$B$7:$D$7,0),"Simple","Medium","Complex"),"Pick from list")) | D11: =IF(B11="","",IFERROR(MATCH(B11,'Complexity Rubric'!$B$7:$D$7,0),""))
A12: Component reuse | B12: Library component with moderate customisation | C12: =IF(B12="","",IFERROR(CHOOSE(MATCH(B12,'Complexity Rubric'!$B$8:$D$8,0),"Simple","Medium","Complex"),"Pick from list")) | D12: =IF(B12="","",IFERROR(MATCH(B12,'Complexity Rubric'!$B$8:$D$8,0),""))
A13: Layout & responsiveness | B13: Adapts to tablet and mobile widths | C13: =IF(B13="","",IFERROR(CHOOSE(MATCH(B13,'Complexity Rubric'!$B$9:$D$9,0),"Simple","Medium","Complex"),"Pick from list")) | D13: =IF(B13="","",IFERROR(MATCH(B13,'Complexity Rubric'!$B$9:$D$9,0),""))
A14: Permissions | B14: Show or hide elements by role | C14: =IF(B14="","",IFERROR(CHOOSE(MATCH(B14,'Complexity Rubric'!$B$10:$D$10,0),"Simple","Medium","Complex"),"Pick from list")) | D14: =IF(B14="","",IFERROR(MATCH(B14,'Complexity Rubric'!$B$10:$D$10,0),""))
A15: Volume of data | B15: Hundreds of rows, paginated | C15: =IF(B15="","",IFERROR(CHOOSE(MATCH(B15,'Complexity Rubric'!$B$11:$D$11,0),"Simple","Medium","Complex"),"Pick from list")) | D15: =IF(B15="","",IFERROR(MATCH(B15,'Complexity Rubric'!$B$11:$D$11,0),""))
A17: Step 2 - result
A18: Dimensions answered | B18: =COUNT($D$9:$D$15)&" of 7"
A19: Recommended level | B19: =CHOOSE(D19,"Simple","Medium","Complex") | D19: =IF(COUNT($D$9:$D$15)=0,2,IF(AND(MAX($D$9:$D$15)=1,COUNT($D$9:$D$15)<7),2,MAX($D$9:$D$15)))
A20: Why | B20: =IF(COUNT($D$9:$D$15)=0,"Nothing selected - default to Medium (Rule 2).",IF(AND(MAX($D$9:$D$15)=1,COUNT($D$9:$D$15)<7),"Only Simple answers so far and some dimensions are unanswered - default to Medium (Rule 2).","Driven by "&INDEX($A$9:$A$15,MATCH(MAX($D$9:$D$15),$D$9:$D$15,0))&": "&INDEX($B$9:$B$15,MATCH(MAX($D$9:$D$15),$D$9:$D$15,0))&" (highest trigger wins, Rule 1)."))
A21: Hours for ONE such page (without AI) | B21: =IFERROR(INDEX('Page Templates'!$G$5:$I$15,MATCH($B$5,'Page Templates'!$A$5:$A$15,0),$D$19),"Choose a page type above")
A22: What to enter on the Estimator | B22: =IF($B$5="","Enter 1 at level "&B19&" for the item.","Section A: add 1 to the # "&B19&" column for "&$B$5&".")
A24: The Advisor does not change the Estimator by itself. It tells you which level to use, so two estimators reading the same requirement reach the same answer.

Sheet Complexity Rubric
A1: Complexity Rubric - what Simple, Medium and Complex mean
A2: Generic rules for classifying any component. Component-specific definitions are in the Component Catalogue.
A4: Dimension | B4: SIMPLE | C4: MEDIUM | D4: COMPLEX
A5: Data source | B5: Static / hard-coded data, or a single API call on page load | C5: Several API calls, or one call with server-side paging, sorting or filtering | D5: Live data (polling, websocket) or chained / dependent API calls
A6: Interaction | B6: Display only; basic click or navigation | C6: Sort, filter, select, open modals, submit forms | D6: Drag-and-drop, inline editing, real-time updates, keyboard shortcuts
A7: States & validation | B7: Default, loading and empty states | C7: Field validation, success and error states, server-error mapping | D7: Conditional or dependent fields, autosave, optimistic updates, partial failures
A8: Component reuse | B8: Used as-is from the component library | C8: Library component with moderate customisation | D8: Substantial custom component or custom rendering
A9: Layout & responsiveness | B9: Single fixed layout | C9: Adapts to tablet and mobile widths | D9: Dense multi-panel layout with reflow and sticky regions
A10: Permissions | B10: None | C10: Show or hide elements by role | D10: Field-level or dynamic permissions
A11: Volume of data | B11: Handful of rows or items | C11: Hundreds of rows, paginated | D11: Thousands of rows or very large payloads (virtualisation)
A13: How to choose a level
A14: Rule 1 - highest trigger wins | B14: Pick the highest level for which ANY one trigger in the table applies. A component that needs live data is Complex even if everything else is simple.
A15: Rule 2 - when unsure | B15: Use Medium as the default. Use Complex for analytics-heavy or real-time screens.
A16: Rule 3 - use component definitions | B16: The Component Catalogue gives a concrete Simple / Medium / Complex description for every component. Where it exists, it overrides this generic rubric.
A17: Rule 4 - hours scale | B17: Hours are for one component, build plus unit test. As a calibration check, Medium is typically about 2x Simple and Complex about 2x Medium.
A18: Example - data table | B18: Simple: static columns loaded once from one API (4 h). Medium: server-side sort, filter and pagination (12 h). Complex: live updates, virtualisation, inline actions (24 h).

Sheet Component Catalogue
A1: Component Catalogue
A2: Generic UI and back-end API components with complexity definitions and effort (developer build + unit test). Edit the blue hours; 'with AI' hours are calculated.
H3: Hours WITHOUT AI | K3: Hours WITH AI (calculated)
A4: Category | B4: Layer | C4: Component | D4: Unit | E4: Simple looks like | F4: Medium looks like | G4: Complex looks like | H4: Simple | I4: Medium | J4: Complex | K4: Simple | L4: Medium | M4: Complex
A5: Foundation & Layout | B5: UI | C5: App shell & routing | D5: per application | E5: Header + content area, up to 3 static routes | F5: Header + sidebar, route guards, 404/error pages | G5: Multiple layouts (public/auth/admin), nested routes, global state, error boundaries | H5: 8 | I5: 16 | J5: 32 | K5: =H5*(1-Assumptions!$B$5) | L5: =I5*(1-Assumptions!$B$5) | M5: =J5*(1-Assumptions!$B$5)
A6: Foundation & Layout | B6: UI | C6: Sidebar navigation | D6: per application | E6: Flat list of links | F6: Grouped links, active state, collapsible | G6: Multi-level nested menu, role-driven items, persisted state | H6: 4 | I6: 8 | J6: 16 | K6: =H6*(1-Assumptions!$B$5) | L6: =I6*(1-Assumptions!$B$5) | M6: =J6*(1-Assumptions!$B$5)
A7: Foundation & Layout | B7: UI | C7: Top header / app bar | D7: per application | E7: Title and static links | F7: Logo, user menu, notification badge | G7: Global search, context/organisation switcher, notification dropdown | H7: 3 | I7: 6 | J7: 12 | K7: =H7*(1-Assumptions!$B$5) | L7: =I7*(1-Assumptions!$B$5) | M7: =J7*(1-Assumptions!$B$5)
A8: Foundation & Layout | B8: UI | C8: Breadcrumbs & tabs | D8: per page | E8: Static breadcrumbs or tabs | F8: Route-driven tabs and breadcrumbs | G8: Data-driven breadcrumbs, guarded or lazy-loaded tabs | H8: 2 | I8: 4 | J8: 8 | K8: =H8*(1-Assumptions!$B$5) | L8: =I8*(1-Assumptions!$B$5) | M8: =J8*(1-Assumptions!$B$5)
A9: Foundation & Layout | B9: UI | C9: Responsive layout | D9: per page | E9: Library grid, 2 breakpoints | F9: Desktop / tablet / mobile adaptation of one page | G9: Reflowing panels, collapsing regions, sticky areas on dense pages | H9: 4 | I9: 8 | J9: 16 | K9: =H9*(1-Assumptions!$B$5) | L9: =I9*(1-Assumptions!$B$5) | M9: =J9*(1-Assumptions!$B$5)
A10: Foundation & Layout | B10: UI | C10: Master-detail view | D10: per view | E10: List + detail pane, static data | F10: API-fed list and detail with synced selection | G10: Editable detail, pagination, deep links, unsaved-changes guard | H10: 8 | I10: 16 | J10: 28 | K10: =H10*(1-Assumptions!$B$5) | L10: =I10*(1-Assumptions!$B$5) | M10: =J10*(1-Assumptions!$B$5)
A11: Foundation & Layout | B11: UI | C11: Theme & design tokens | D11: per application | E11: Component-library theme with brand colours | F11: Light/dark toggle, persisted preference | G11: Custom design-system tokens, multiple brands/themes | H11: 4 | I11: 12 | J11: 24 | K11: =H11*(1-Assumptions!$B$5) | L11: =I11*(1-Assumptions!$B$5) | M11: =J11*(1-Assumptions!$B$5)
A12: Foundation & Layout | B12: UI | C12: Static content section | D12: per section | E12: Text and images (e.g. footer, info block) | F12: Media, accordion, anchors, FAQ | G12: CMS-driven or highly interactive content | H12: 3 | I12: 6 | J12: 12 | K12: =H12*(1-Assumptions!$B$5) | L12: =I12*(1-Assumptions!$B$5) | M12: =J12*(1-Assumptions!$B$5)
A13: Foundation & Layout | B13: UI | C13: Localisation (i18n) | D13: per application | E13: One extra language, static strings | F13: Runtime language switch, locale date/number formats | G13: RTL support, pluralisation, per-user locale persistence | H13: 6 | I13: 12 | J13: 24 | K13: =H13*(1-Assumptions!$B$5) | L13: =I13*(1-Assumptions!$B$5) | M13: =J13*(1-Assumptions!$B$5)
A14: Data Display | B14: UI | C14: Data table | D14: per table | E14: Static columns, one API, loaded on page load, no interaction | F14: Server-side sort / filter / pagination, formatted columns | G14: Live updates (polling/websocket), virtualisation, column configuration, inline actions | H14: 4 | I14: 12 | J14: 24 | K14: =H14*(1-Assumptions!$B$5) | L14: =I14*(1-Assumptions!$B$5) | M14: =J14*(1-Assumptions!$B$5)
A15: Data Display | B15: UI | C15: Row actions & bulk selection | D15: per table | E15: Edit/delete icons per row | F15: Row selection, bulk action menu, confirmation | G15: Permission-driven actions, async batch operations with progress | H15: 4 | I15: 8 | J15: 16 | K15: =H15*(1-Assumptions!$B$5) | L15: =I15*(1-Assumptions!$B$5) | M15: =J15*(1-Assumptions!$B$5)
A16: Data Display | B16: UI | C16: Editable data grid | D16: per grid | E16: Inline edit of one field type | F16: Several editor types, per-cell validation | G16: Spreadsheet-style editing, bulk edit, undo, autosave, large data sets | H16: 12 | I16: 20 | J16: 36 | K16: =H16*(1-Assumptions!$B$5) | L16: =I16*(1-Assumptions!$B$5) | M16: =J16*(1-Assumptions!$B$5)
... A67: Backend API | B67: API | C67: Agent / LLM-facing endpoint | D67: per endpoint | E67: Pass-through request/response to an existing agent | F67: Streaming, session context | G67: Multi-step orchestration, tool-call events | H67: 8 | I67: 16 | J67: 32 | K67: =H67*(1-Assumptions!$B$5) | L67: =I67*(1-Assumptions!$B$5) | M67: =J67*(1-Assumptions!$B$5)

Sheet Page Templates
A1: Page Templates
A2: Typical effort for a whole page type at Simple / Medium / Complex level. Hours roll up from 'Page Bundles' and the Component Catalogue. Use these when the RFP only tells you the number and type of pages.
G3: Hours per page (without AI) | J3: Components that make up the page (as delivered - Page Bundles is the live source)
A4: Page type | B4: What it covers | C4: Typical API endpoints needed | D4: Simple page = | E4: Medium page = | F4: Complex page = | G4: Simple | H4: Medium | I4: Complex | J4: Simple page components | K4: Medium page components | L4: Complex page components
A5: Login & authentication page | B5: Sign-in screen and account flows | C5: 1-3 (auth, token, reset) | D5: Login form only | E5: Login with SSO redirect, reset link, error states | F5: MFA, multiple identity providers, lockout flows | G5: =SUMIFS('Page Bundles'!$I$5:$I$300,'Page Bundles'!$A$5:$A$300,$A5) | H5: =SUMIFS('Page Bundles'!$J$5:$J$300,'Page Bundles'!$A$5:$A$300,$A5) | I5: =SUMIFS('Page Bundles'!$K$5:$K$300,'Page Bundles'!$A$5:$A$300,$A5) | J5: Login screen (Simple) | K5: Login screen (Medium) Password reset & account flows (Simple) Session handling (Simple) | L5: Login screen (Complex) Password reset & account flows (Medium) Session handling (Medium)
A6: Dashboard / analytics page | B6: KPI cards, charts and supporting tables | C6: 2-6 (aggregation, list) | D6: Up to 4 KPIs and 1-2 basic charts, static filters | E6: 3-5 charts, shared date filter, one detail table | F6: 6+ charts, drill-down, live data, multiple data sources | G6: =SUMIFS('Page Bundles'!$I$5:$I$300,'Page Bundles'!$A$5:$A$300,$A6) | H6: =SUMIFS('Page Bundles'!$J$5:$J$300,'Page Bundles'!$A$5:$A$300,$A6) | I6: =SUMIFS('Page Bundles'!$K$5:$K$300,'Page Bundles'!$A$5:$A$300,$A6) | J6: Dashboard layout & global filters (Simple) 4 x KPI / stat card (Simple) 2 x Standard chart (bar, line, area, pie) (Simple) Empty, loading & error states (Simple) | K6: Dashboard layout & global filters (Medium) 4 x KPI / stat card (Simple) 4 x Standard chart (bar, line, area, pie) (Medium) Data table (Simple) Empty, loading & error states (Medium) | L6: Dashboard layout & global filters (Complex) 6 x KPI / stat card (Medium) 6 x Standard chart (bar, line, area, pie) (Complex) 2 x Specialised chart (funnel, gauge, heatmap, scatter) (Medium) Data table (Medium) 2 x Drill-down interaction (Medium) Empty, loading & error states (Medium)
A7: List / search page | B7: Table with filters and actions | C7: 1-3 (list, search, export) | D7: One read-only table with 2-3 filters | E7: Server-side table with filters, row actions, export | F7: Bulk actions, advanced filters, live updates, saved views | G7: =SUMIFS('Page Bundles'!$I$5:$I$300,'Page Bundles'!$A$5:$A$300,$A7) | H7: =SUMIFS('Page Bundles'!$J$5:$J$300,'Page Bundles'!$A$5:$A$300,$A7) | I7: =SUMIFS('Page Bundles'!$K$5:$K$300,'Page Bundles'!$A$5:$A$300,$A7) | J7: Data table (Simple) Filter bar / panel (Simple) Empty, loading & error states (Simple) | K7: Data table (Medium) Filter bar / panel (Medium) Search box & suggestions (Simple) Row actions & bulk selection (Medium) Data export (CSV / Excel) (Simple) Empty, loading & error states (Medium) | L7: Data table (Complex) Filter bar / panel (Complex) Search box & suggestions (Medium) Row actions & bulk selection (Complex) Data export (CSV / Excel) (Medium) Empty, loading & error states (Medium)
A8: Detail / record page | B8: Summary, tabs, related data and activity | C8: 2-5 (read, update, related lists) | D8: Read-only summary, no tabs | E8: Tabs, a related table, edit action | F8: Inline edit, several related sections, activity timeline, permissions | G8: =SUMIFS('Page Bundles'!$I$5:$I$300,'Page Bundles'!$A$5:$A$300,$A8) | H8: =SUMIFS('Page Bundles'!$J$5:$J$300,'Page Bundles'!$A$5:$A$300,$A8) | I8: =SUMIFS('Page Bundles'!$K$5:$K$300,'Page Bundles'!$A$5:$A$300,$A8) | J8: Detail / summary panel (Simple) Empty, loading & error states (Simple) | K8: Detail / summary panel (Medium) Breadcrumbs & tabs (Medium) Data table (Simple) Timeline / activity feed (Simple) Modal / dialog (Simple) Empty, loading & error states (Medium) | L8: Detail / summary panel (Complex) Breadcrumbs & tabs (Complex) 2 x Data table (Medium) Timeline / activity feed (Medium) 2 x Modal / dialog (Medium) Empty, loading & error states (Medium)
A9: Form / data-entry page | B9: Create or edit a record | C9: 1-3 (create, update, lookups) | D9: One form of up to 5 fields | E9: 6-12 fields, validation, file attachment | F9: Conditional sections, autosave, many field types | G9: =SUMIFS('Page Bundles'!$I$5:$I$300,'Page Bundles'!$A$5:$A$300,$A9) | H9: =SUMIFS('Page Bundles'!$J$5:$J$300,'Page Bundles'!$A$5:$A$300,$A9) | I9: =SUMIFS('Page Bundles'!$K$5:$K$300,'Page Bundles'!$A$5:$A$300,$A9) | J9: Form (create / edit) (Simple) Select / dropdown / combobox (Simple) Empty, loading & error states (Simple) | K9: Form (create / edit) (Medium) 3 x Select / dropdown / combobox (Simple) Date / date-range picker (Simple) File upload (Simple) Empty, loading & error states (Medium) | L9: Form (create / edit) (Complex) 6 x Select / dropdown / combobox (Medium) 2 x Date / date-range picker (Medium) File upload (Medium) Empty, loading & error states (Medium)
A10: Wizard / guided workflow page | B10: Step-by-step process | C10: 2-6 (per-step save, lookups, submit) | D10: 2-3 linear steps | E10: 4-5 steps with review step | F10: Branching steps, save/resume, approvals | G10: =SUMIFS('Page Bundles'!$I$5:$I$300,'Page Bundles'!$A$5:$A$300,$A10) | H10: =SUMIFS('Page Bundles'!$J$5:$J$300,'Page Bundles'!$A$5:$A$300,$A10) | I10: =SUMIFS('Page Bundles'!$K$5:$K$300,'Page Bundles'!$A$5:$A$300,$A10) | J10: Multi-step wizard (Simple) 2 x Select / dropdown / combobox (Simple) Modal / dialog (Simple) Empty, loading & error states (Simple) | K10: Multi-step wizard (Medium) 4 x Select / dropdown / combobox (Simple) Date / date-range picker (Simple) Modal / dialog (Simple) Empty, loading & error states (Medium) | L10: Multi-step wizard (Complex) 6 x Select / dropdown / combobox (Medium) 2 x Date / date-range picker (Medium) 2 x Modal / dialog (Medium) Empty, loading & error states (Medium)
A11: Admin / configuration page | B11: User, role and settings management | C11: 3-8 (users, roles, settings, audit) | D11: A single settings form or user list | E11: User management, roles and audit log | F11: Permission matrix, bulk operations, delegated admin | G11: =SUMIFS('Page Bundles'!$I$5:$I$300,'Page Bundles'!$A$5:$A$300,$A11) | H11: =SUMIFS('Page Bundles'!$J$5:$J$300,'Page Bundles'!$A$5:$A$300,$A11) | I11: =SUMIFS('Page Bundles'!$K$5:$K$300,'Page Bundles'!$A$5:$A$300,$A11) | J11: User & role management (Simple) Data table (Simple) Settings / preferences panel (Simple) Modal / dialog (Simple) Empty, loading & error states (Simple) | K11: User & role management (Medium) Data table (Medium) Settings / preferences panel (Medium) Role & permission editor (Simple) Audit log viewer (Simple) 2 x Modal / dialog (Simple) Empty, loading & error states (Medium) | L11: User & role management (Complex) Data table (Complex) Settings / preferences panel (Complex) Role & permission editor (Medium) Audit log viewer (Medium) 3 x Modal / dialog (Medium) Empty, loading & error states (Medium)
A12: AI chat assistant page | B12: Conversational interface to an agent | C12: 2-5 (chat, history, feedback, stream) | D12: Single-thread request/response chat | E12: Streaming, markdown, conversation history, citations | F12: Attachments, tool-call display, multi-session, structured output | G12: =SUMIFS('Page Bundles'!$I$5:$I$300,'Page Bundles'!$A$5:$A$300,$A12) | H12: =SUMIFS('Page Bundles'!$J$5:$J$300,'Page Bundles'!$A$5:$A$300,$A12) | I12: =SUMIFS('Page Bundles'!$K$5:$K$300,'Page Bundles'!$A$5:$A$300,$A12) | J12: Chat interface (Simple) Empty, loading & error states (Simple) | K12: Chat interface (Medium) Master-detail view (Simple) Citations & sources panel (Simple) AI feedback & suggested prompts (Simple) Empty, loading & error states (Medium) | L12: Chat interface (Complex) Master-detail view (Medium) Citations & sources panel (Medium) AI feedback & suggested prompts (Medium) AI structured-output renderer (Medium) Empty, loading & error states (Medium)
A13: Agent / workflow monitor page | B13: Run list, run detail and approvals | C13: 3-8 (runs, steps, approvals, status) | D13: Run list with status | E13: Live run detail with step timeline | F13: Approvals, retries, drill-down, multi-agent view | G13: =SUMIFS('Page Bundles'!$I$5:$I$300,'Page Bundles'!$A$5:$A$300,$A13) | H13: =SUMIFS('Page Bundles'!$J$5:$J$300,'Page Bundles'!$A$5:$A$300,$A13) | I13: =SUMIFS('Page Bundles'!$K$5:$K$300,'Page Bundles'!$A$5:$A$300,$A13) | J13: Data table (Simple) Detail / summary panel (Simple) Agent run / tool-call timeline (Simple) Empty, loading & error states (Simple) | K13: Data table (Medium) Detail / summary panel (Medium) Agent run / tool-call timeline (Medium) Human-in-the-loop approval (Simple) Progress & job status (Simple) Filter bar / panel (Simple) Empty, loading & error states (Medium) | L13: Data table (Complex) Detail / summary panel (Complex) Agent run / tool-call timeline (Complex) Human-in-the-loop approval (Medium) Progress & job status (Medium) Filter bar / panel (Medium) Empty, loading & error states (Medium)
A14: Report & export page | B14: Filtered report with downloads | C14: 2-5 (query, aggregate, export) | D14: Single table report with CSV export | E14: Filters, charts, Excel/PDF export | F14: Multi-section branded report, asynchronous generation | G14: =SUMIFS('Page Bundles'!$I$5:$I$300,'Page Bundles'!$A$5:$A$300,$A14) | H14: =SUMIFS('Page Bundles'!$J$5:$J$300,'Page Bundles'!$A$5:$A$300,$A14) | I14: =SUMIFS('Page Bundles'!$K$5:$K$300,'Page Bundles'!$A$5:$A$300,$A14) | J14: Filter bar / panel (Simple) Data table (Simple) Data export (CSV / Excel) (Simple) Empty, loading & error states (Simple) | K14: Filter bar / panel (Medium) Data table (Medium) 2 x Standard chart (bar, line, area, pie) (Simple) Data export (CSV / Excel) (Medium) PDF / printable report (Medium) Empty, loading & error states (Medium) | L14: Filter bar / panel (Complex) Data table (Complex) 4 x Standard chart (bar, line, area, pie) (Medium) Data export (CSV / Excel) (Complex) PDF / printable report (Complex) Empty, loading & error states (Medium)
A15: Content / landing page | B15: Static or lightly interactive content | C15: 0-1 | D15: Text and images | E15: Sections, accordion, anchors | F15: Highly interactive or CMS-driven content | G15: =SUMIFS('Page Bundles'!$I$5:$I$300,'Page Bundles'!$A$5:$A$300,$A15) | H15: =SUMIFS('Page Bundles'!$J$5:$J$300,'Page Bundles'!$A$5:$A$300,$A15) | I15: =SUMIFS('Page Bundles'!$K$5:$K$300,'Page Bundles'!$A$5:$A$300,$A15) | J15: 2 x Static content section (Simple) Responsive layout (Simple) | K15: 4 x Static content section (Medium) Responsive layout (Medium) | L15: 6 x Static content section (Medium) Responsive layout (Complex)
A17: Page hours cover the page's own components only. Add shared items once per application (app shell, navigation, theme, role-based rendering, session handling) in Section B of the Estimator, and the back-end APIs in Section C. 'Typical API endpoints' is a guide for choosing API counts.

Sheet Page Bundles
A1: Page Bundles (detail behind Page Templates)
A2: Which catalogue components make up each page type at Simple / Medium / Complex page level. Quantity 0 = component not in that page level. Edit quantities and levels to tune a template.
C3: Quantity per page | F3: Complexity of component | I3: Hours (without AI) | L3: Helper keys (do not edit) - used by the Estimator's Page Explorer. Copy down when adding rows.
A4: Page type | B4: Component | C4: Simple page | D4: Medium page | E4: Complex page | F4: Simple page | G4: Medium page | H4: Complex page | I4: Simple page | J4: Medium page | K4: Complex page | L4: Simple key | M4: Medium key | N4: Complex key
A5: Login & authentication page | B5: Login screen | C5: 1 | D5: 1 | E5: 1 | F5: Simple | G5: Medium | H5: Complex | I5: =IF(C5=0,0,C5*INDEX('Component Catalogue'!$H$5:$J$150,MATCH($B5,'Component Catalogue'!$C$5:$C$150,0),MATCH(F5,'Component Catalogue'!$H$4:$J$4,0))) | J5: =IF(D5=0,0,D5*INDEX('Component Catalogue'!$H$5:$J$150,MATCH($B5,'Component Catalogue'!$C$5:$C$150,0),MATCH(G5,'Component Catalogue'!$H$4:$J$4,0))) | K5: =IF(E5=0,0,E5*INDEX('Component Catalogue'!$H$5:$J$150,MATCH($B5,'Component Catalogue'!$C$5:$C$150,0),MATCH(H5,'Component Catalogue'!$H$4:$J$4,0))) | L5: =IF(C5>0,$A5&"|"&COUNTIFS($A$5:$A5,$A5,C$5:C5,">0"),"") | M5: =IF(D5>0,$A5&"|"&COUNTIFS($A$5:$A5,$A5,D$5:D5,">0"),"") | N5: =IF(E5>0,$A5&"|"&COUNTIFS($A$5:$A5,$A5,E$5:E5,">0"),"")
A6: Login & authentication page | B6: Password reset & account flows | C6: 0 | D6: 1 | E6: 1 | F6: - | G6: Simple | H6: Medium | I6: =IF(C6=0,0,C6*INDEX('Component Catalogue'!$H$5:$J$150,MATCH($B6,'Component Catalogue'!$C$5:$C$150,0),MATCH(F6,'Component Catalogue'!$H$4:$J$4,0))) | J6: =IF(D6=0,0,D6*INDEX('Component Catalogue'!$H$5:$J$150,MATCH($B6,'Component Catalogue'!$C$5:$C$150,0),MATCH(G6,'Component Catalogue'!$H$4:$J$4,0))) | K6: =IF(E6=0,0,E6*INDEX('Component Catalogue'!$H$5:$J$150,MATCH($B6,'Component Catalogue'!$C$5:$C$150,0),MATCH(H6,'Component Catalogue'!$H$4:$J$4,0))) | L6: =IF(C6>0,$A6&"|"&COUNTIFS($A$5:$A6,$A6,C$5:C6,">0"),"") | M6: =IF(D6>0,$A6&"|"&COUNTIFS($A$5:$A6,$A6,D$5:D6,">0"),"") | N6: =IF(E6>0,$A6&"|"&COUNTIFS($A$5:$A6,$A6,E$5:E6,">0"),"")
A7: Login & authentication page | B7: Session handling | C7: 0 | D7: 1 | E7: 1 | F7: - | G7: Simple | H7: Medium | I7: =IF(C7=0,0,C7*INDEX('Component Catalogue'!$H$5:$J$150,MATCH($B7,'Component Catalogue'!$C$5:$C$150,0),MATCH(F7,'Component Catalogue'!$H$4:$J$4,0))) | J7: =IF(D7=0,0,D7*INDEX('Component Catalogue'!$H$5:$J$150,MATCH($B7,'Component Catalogue'!$C$5:$C$150,0),MATCH(G7,'Component Catalogue'!$H$4:$J$4,0))) | K7: =IF(E7=0,0,E7*INDEX('Component Catalogue'!$H$5:$J$150,MATCH($B7,'Component Catalogue'!$C$5:$C$150,0),MATCH(H7,'Component Catalogue'!$H$4:$J$4,0))) | L7: =IF(C7>0,$A7&"|"&COUNTIFS($A$5:$A7,$A7,C$5:C7,">0"),"") | M7: =IF(D7>0,$A7&"|"&COUNTIFS($A$5:$A7,$A7,D$5:D7,">0"),"") | N7: =IF(E7>0,$A7&"|"&COUNTIFS($A$5:$A7,$A7,E$5:E7,">0"),"")
A8: Dashboard / analytics page | B8: Dashboard layout & global filters | C8: 1 | D8: 1 | E8: 1 | F8: Simple | G8: Medium | H8: Complex | I8: =IF(C8=0,0,C8*INDEX('Component Catalogue'!$H$5:$J$150,MATCH($B8,'Component Catalogue'!$C$5:$C$150,0),MATCH(F8,'Component Catalogue'!$H$4:$J$4,0))) | J8: =IF(D8=0,0,D8*INDEX('Component Catalogue'!$H$5:$J$150,MATCH($B8,'Component Catalogue'!$C$5:$C$150,0),MATCH(G8,'Component Catalogue'!$H$4:$J$4,0))) | K8: =IF(E8=0,0,E8*INDEX('Component Catalogue'!$H$5:$J$150,MATCH($B8,'Component Catalogue'!$C$5:$C$150,0),MATCH(H8,'Component Catalogue'!$H$4:$J$4,0))) | L8: =IF(C8>0,$A8&"|"&COUNTIFS($A$5:$A8,$A8,C$5:C8,">0"),"") | M8: =IF(D8>0,$A8&"|"&COUNTIFS($A$5:$A8,$A8,D$5:D8,">0"),"") | N8: =IF(E8>0,$A8&"|"&COUNTIFS($A$5:$A8,$A8,E$5:E8,">0"),"")
A9: Dashboard / analytics page | B9: KPI / stat card | C9: 4 | D9: 4 | E9: 6 | F9: Simple | G9: Simple | H9: Medium | I9: =IF(C9=0,0,C9*INDEX('Component Catalogue'!$H$5:$J$150,MATCH($B9,'Component Catalogue'!$C$5:$C$150,0),MATCH(F9,'Component Catalogue'!$H$4:$J$4,0))) | J9: =IF(D9=0,0,D9*INDEX('Component Catalogue'!$H$5:$J$150,MATCH($B9,'Component Catalogue'!$C$5:$C$150,0),MATCH(G9,'Component Catalogue'!$H$4:$J$4,0))) | K9: =IF(E9=0,0,E9*INDEX('Component Catalogue'!$H$5:$J$150,MATCH($B9,'Component Catalogue'!$C$5:$C$150,0),MATCH(H9,'Component Catalogue'!$H$4:$J$4,0))) | L9: =IF(C9>0,$A9&"|"&COUNTIFS($A$5:$A9,$A9,C$5:C9,">0"),"") | M9: =IF(D9>0,$A9&"|"&COUNTIFS($A$5:$A9,$A9,D$5:D9,">0"),"") | N9: =IF(E9>0,$A9&"|"&COUNTIFS($A$5:$A9,$A9,E$5:E9,">0"),"")
A10: Dashboard / analytics page | B10: Standard chart (bar, line, area, pie) | C10: 2 | D10: 4 | E10: 6 | F10: Simple | G10: Medium | H10: Complex | I10: =IF(C10=0,0,C10*INDEX('Component Catalogue'!$H$5:$J$150,MATCH($B10,'Component Catalogue'!$C$5:$C$150,0),MATCH(F10,'Component Catalogue'!$H$4:$J$4,0))) | J10: =IF(D10=0,0,D10*INDEX('Component Catalogue'!$H$5:$J$150,MATCH($B10,'Component Catalogue'!$C$5:$C$150,0),MATCH(G10,'Component Catalogue'!$H$4:$J$4,0))) | K10: =IF(E10=0,0,E10*INDEX('Component Catalogue'!$H$5:$J$150,MATCH($B10,'Component Catalogue'!$C$5:$C$150,0),MATCH(H10,'Component Catalogue'!$H$4:$J$4,0))) | L10: =IF(C10>0,$A10&"|"&COUNTIFS($A$5:$A10,$A10,C$5:C10,">0"),"") | M10: =IF(D10>0,$A10&"|"&COUNTIFS($A$5:$A10,$A10,D$5:D10,">0"),"") | N10: =IF(E10>0,$A10&"|"&COUNTIFS($A$5:$A10,$A10,E$5:E10,">0"),"")
A11: Dashboard / analytics page | B11: Specialised chart (funnel, gauge, heatmap, scatter) | C11: 0 | D11: 0 | E11: 2 | F11: - | G11: - | H11: Medium | I11: =IF(C11=0,0,C11*INDEX('Component Catalogue'!$H$5:$J$150,MATCH($B11,'Component Catalogue'!$C$5:$C$150,0),MATCH(F11,'Component Catalogue'!$H$4:$J$4,0))) | J11: =IF(D11=0,0,D11*INDEX('Component Catalogue'!$H$5:$J$150,MATCH($B11,'Component Catalogue'!$C$5:$C$150,0),MATCH(G11,'Component Catalogue'!$H$4:$J$4,0))) | K11: =IF(E11=0,0,E11*INDEX('Component Catalogue'!$H$5:$J$150,MATCH($B11,'Component Catalogue'!$C$5:$C$150,0),MATCH(H11,'Component Catalogue'!$H$4:$J$4,0))) | L11: =IF(C11>0,$A11&"|"&COUNTIFS($A$5:$A11,$A11,C$5:C11,">0"),"") | M11: =IF(D11>0,$A11&"|"&COUNTIFS($A$5:$A11,$A11,D$5:D11,">0"),"") | N11: =IF(E11>0,$A11&"|"&COUNTIFS($A$5:$A11,$A11,E$5:E11,">0"),"")
A12: Dashboard / analytics page | B12: Data table | C12: 0 | D12: 1 | E12: 1 | F12: - | G12: Simple | H12: Medium | I12: =IF(C12=0,0,C12*INDEX('Component Catalogue'!$H$5:$J$150,MATCH($B12,'Component Catalogue'!$C$5:$C$150,0),MATCH(F12,'Component Catalogue'!$H$4:$J$4,0))) | J12: =IF(D12=0,0,D12*INDEX('Component Catalogue'!$H$5:$J$150,MATCH($B12,'Component Catalogue'!$C$5:$C$150,0),MATCH(G12,'Component Catalogue'!$H$4:$J$4,0))) | K12: =IF(E12=0,0,E12*INDEX('Component Catalogue'!$H$5:$J$150,MATCH($B12,'Component Catalogue'!$C$5:$C$150,0),MATCH(H12,'Component Catalogue'!$H$4:$J$4,0))) | L12: =IF(C12>0,$A12&"|"&COUNTIFS($A$5:$A12,$A12,C$5:C12,">0"),"") | M12: =IF(D12>0,$A12&"|"&COUNTIFS($A$5:$A12,$A12,D$5:D12,">0"),"") | N12: =IF(E12>0,$A12&"|"&COUNTIFS($A$5:$A12,$A12,E$5:E12,">0"),"")
A13: Dashboard / analytics page | B13: Drill-down interaction | C13: 0 | D13: 0 | E13: 2 | F13: - | G13: - | H13: Medium | I13: =IF(C13=0,0,C13*INDEX('Component Catalogue'!$H$5:$J$150,MATCH($B13,'Component Catalogue'!$C$5:$C$150,0),MATCH(F13,'Component Catalogue'!$H$4:$J$4,0))) | J13: =IF(D13=0,0,D13*INDEX('Component Catalogue'!$H$5:$J$150,MATCH($B13,'Component Catalogue'!$C$5:$C$150,0),MATCH(G13,'Component Catalogue'!$H$4:$J$4,0))) | K13: =IF(E13=0,0,E13*INDEX('Component Catalogue'!$H$5:$J$150,MATCH($B13,'Component Catalogue'!$C$5:$C$150,0),MATCH(H13,'Component Catalogue'!$H$4:$J$4,0))) | L13: =IF(C13>0,$A13&"|"&COUNTIFS($A$5:$A13,$A13,C$5:C13,">0"),"") | M13: =IF(D13>0,$A13&"|"&COUNTIFS($A$5:$A13,$A13,D$5:D13,">0"),"") | N13: =IF(E13>0,$A13&"|"&COUNTIFS($A$5:$A13,$A13,E$5:E13,">0"),"")
A14: Dashboard / analytics page | B14: Empty, loading & error states | C14: 1 | D14: 1 | E14: 1 | F14: Simple | G14: Medium | H14: Medium | I14: =IF(C14=0,0,C14*INDEX('Component Catalogue'!$H$5:$J$150,MATCH($B14,'Component Catalogue'!$C$5:$C$150,0),MATCH(F14,'Component Catalogue'!$H$4:$J$4,0))) | J14: =IF(D14=0,0,D14*INDEX('Component Catalogue'!$H$5:$J$150,MATCH($B14,'Component Catalogue'!$C$5:$C$150,0),MATCH(G14,'Component Catalogue'!$H$4:$J$4,0))) | K14: =IF(E14=0,0,E14*INDEX('Component Catalogue'!$H$5:$J$150,MATCH($B14,'Component Catalogue'!$C$5:$C$150,0),MATCH(H14,'Component Catalogue'!$H$4:$J$4,0))) | L14: =IF(C14>0,$A14&"|"&COUNTIFS($A$5:$A14,$A14,C$5:C14,">0"),"") | M14: =IF(D14>0,$A14&"|"&COUNTIFS($A$5:$A14,$A14,D$5:D14,">0"),"") | N14: =IF(E14>0,$A14&"|"&COUNTIFS($A$5:$A14,$A14,E$5:E14,">0"),"")
A15: List / search page | B15: Data table | C15: 1 | D15: 1 | E15: 1 | F15: Simple | G15: Medium | H15: Complex | I15: =IF(C15=0,0,C15*INDEX('Component Catalogue'!$H$5:$J$150,MATCH($B15,'Component Catalogue'!$C$5:$C$150,0),MATCH(F15,'Component Catalogue'!$H$4:$J$4,0))) | J15: =IF(D15=0,0,D15*INDEX('Component Catalogue'!$H$5:$J$150,MATCH($B15,'Component Catalogue'!$C$5:$C$150,0),MATCH(G15,'Component Catalogue'!$H$4:$J$4,0))) | K15: =IF(E15=0,0,E15*INDEX('Component Catalogue'!$H$5:$J$150,MATCH($B15,'Component Catalogue'!$C$5:$C$150,0),MATCH(H15,'Component Catalogue'!$H$4:$J$4,0))) | L15: =IF(C15>0,$A15&"|"&COUNTIFS($A$5:$A15,$A15,C$5:C15,">0"),"") | M15: =IF(D15>0,$A15&"|"&COUNTIFS($A$5:$A15,$A15,D$5:D15,">0"),"") | N15: =IF(E15>0,$A15&"|"&COUNTIFS($A$5:$A15,$A15,E$5:E15,">0"),"")
A16: List / search page | B16: Filter bar / panel | C16: 1 | D16: 1 | E16: 1 | F16: Simple | G16: Medium | H16: Complex | I16: =IF(C16=0,0,C16*INDEX('Component Catalogue'!$H$5:$J$150,MATCH($B16,'Component Catalogue'!$C$5:$C$150,0),MATCH(F16,'Component Catalogue'!$H$4:$J$4,0))) | J16: =IF(D16=0,0,D16*INDEX('Component Catalogue'!$H$5:$J$150,MATCH($B16,'Component Catalogue'!$C$5:$C$150,0),MATCH(G16,'Component Catalogue'!$H$4:$J$4,0))) | K16: =IF(E16=0,0,E16*INDEX('Component Catalogue'!$H$5:$J$150,MATCH($B16,'Component Catalogue'!$C$5:$C$150,0),MATCH(H16,'Component Catalogue'!$H$4:$J$4,0))) | L16: =IF(C16>0,$A16&"|"&COUNTIFS($A$5:$A16,$A16,C$5:C16,">0"),"") | M16: =IF(D16>0,$A16&"|"&COUNTIFS($A$5:$A16,$A16,D$5:D16,">0"),"") | N16: =IF(E16>0,$A16&"|"&COUNTIFS($A$5:$A16,$A16,E$5:E16,">0"),"")
... A64: Content / landing page | B64: Responsive layout | C64: 1 | D64: 1 | E64: 1 | F64: Simple | G64: Medium | H64: Complex | I64: =IF(C64=0,0,C64*INDEX('Component Catalogue'!$H$5:$J$150,MATCH($B64,'Component Catalogue'!$C$5:$C$150,0),MATCH(F64,'Component Catalogue'!$H$4:$J$4,0))) | J64: =IF(D64=0,0,D64*INDEX('Component Catalogue'!$H$5:$J$150,MATCH($B64,'Component Catalogue'!$C$5:$C$150,0),MATCH(G64,'Component Catalogue'!$H$4:$J$4,0))) | K64: =IF(E64=0,0,E64*INDEX('Component Catalogue'!$H$5:$J$150,MATCH($B64,'Component Catalogue'!$C$5:$C$150,0),MATCH(H64,'Component Catalogue'!$H$4:$J$4,0))) | L64: =IF(C64>0,$A64&"|"&COUNTIFS($A$5:$A64,$A64,C$5:C64,">0"),"") | M64: =IF(D64>0,$A64&"|"&COUNTIFS($A$5:$A64,$A64,D$5:D64,">0"),"") | N64: =IF(E64>0,$A64&"|"&COUNTIFS($A$5:$A64,$A64,E$5:E64,">0"),"")

Sheet Assumptions
A1: Assumptions & Calibration
A2: Editable parameters used across the workbook. Blue text on yellow = input.
A4: Parameter | B4: Value | C4: Notes
A5: AI-assist effort reduction | B5: 0.3 | C5: PLACEHOLDER. Share of effort saved when developers use an AI coding assistant (e.g. Copilot). To be replaced with a figure validated by delivery teams.
A6: Technology factor | B6: 1 | C6: Multiplier on total effort. 1.00 = baseline stack (Next.js/React + TypeScript + a component library). Raise it for stacks that need more hand-built UI (e.g. 1.25 if most components are built by hand).
A7: Hours per person-day | B7: 8 | C7: Used to convert hours into person-days.
A8: Productive hours per person-week | B8: 40 | C8: Used only for the indicative duration on the Estimator sheet.
A11: Baseline assumptions behind the hours
A12: What the hours cover | B12: Developer effort to build the component AND write its unit tests, for a typical first implementation.
A13: What the hours exclude | B13: UAT, integration/system testing, project management, requirements gathering, DevOps/infrastructure, database design and data pipelines.
A14: Who does the work | B14: An average Kyndryl developer. Hours are generic, not person-specific.
A15: Platform | B15: Modern web applications only. No mobile apps, desktop apps or legacy server-rendered stacks.
A16: Front-end baseline | B16: Next.js / React with TypeScript and an established component library (e.g. MUI, Ant Design, shadcn/ui). Approved designs are available before build starts.
A17: Back-end baseline | B17: REST APIs (e.g. Python/FastAPI or Node). Includes routing, validation, business logic, error handling, unit tests and API documentation. Data is accessed through APIs, not direct database connections.
A18: Agent / AI back-end | B18: Agent, pipeline and RAG development is NOT estimated here. Only the UI and API layer that talk to agents are covered.
A19: Hours status | B19: DRAFT starting values. Team members enter their own experience-based hours here. Hours must be generic, i.e. deliverable by any Kyndryl developer, not person-specific.
A22: Calibration log (optional - record delivered projects to refine the hours)
A23: Project / scope summary | B23: Estimated hrs | C23: Actual hrs | D23: Variance % | E23: Lessons / reason
D24: =IF(OR(B24="",B24=0,C24=""),"",(C24-B24)/B24)
D25: =IF(OR(B25="",B25=0,C25=""),"",(C25-B25)/B25)
D26: =IF(OR(B26="",B26=0,C26=""),"",(C26-B26)/B26)
D27: =IF(OR(B27="",B27=0,C27=""),"",(C27-B27)/B27)
D28: =IF(OR(B28="",B28=0,C28=""),"",(C28-B28)/B28)
D29: =IF(OR(B29="",B29=0,C29=""),"",(C29-B29)/B29)
D30: =IF(OR(B30="",B30=0,C30=""),"",(C30-B30)/B30)
D31: =IF(OR(B31="",B31=0,C31=""),"",(C31-B31)/B31)
